<mujoco model="left_shadow_hand">

  <option impratio="10"/>

  <default>
      <default class="left_hand">
          <mesh scale="0.001 0.001 0.001"/>
          <joint axis="1 0 0" damping="0.05" armature="0.0002" frictionloss="0.01"/>
          <position forcerange="-1 1"/>

          <default class="left_wrist">
              <joint damping="0.5"/>
              <default class="left_wrist_y">
                  <joint axis="0 -1 0" range="-0.523599 0.174533"/>
                  <position kp="10" ctrlrange="-0.523599 0.174533" forcerange="-10 10"/>
              </default>
              <default class="left_wrist_x">
                  <joint range="-0.698132 0.488692"/>
                  <position kp="8" ctrlrange="-0.698132 0.488692" forcerange="-5 5"/>
              </default>
          </default>

          <default class="left_thumb">
              <default class="left_thbase">
                  <joint axis="0 0 1" range="-1.0472 1.0472"/>
                  <position kp="0.4" ctrlrange="-1.0472 1.0472" forcerange="-3 3"/>
              </default>
              <default class="left_thproximal">
                  <joint axis="-1 0 0" range="0 1.22173"/>
                  <position ctrlrange="0 1.22173" forcerange="-2 2"/>
              </default>
              <default class="left_thhub">
                  <joint axis="-1 0 0" range="-0.20944 0.20944"/>
                  <position kp="0.5" ctrlrange="-0.20944 0.20944"/>
              </default>
              <default class="left_thmiddle">
                  <joint axis="0 -1 0" range="-0.698132 0.698132"/>
                  <position kp="1.5" ctrlrange="-0.698132 0.698132"/>
              </default>
              <default class="left_thdistal">
                  <joint range="-0.261799 1.5708"/>
                  <position ctrlrange="-0.261799 1.5708"/>
              </default>
          </default>

          <default class="left_metacarpal">
              <joint axis="0.573576 0 0.819152" range="0 0.785398"/>
              <position ctrlrange="0 0.785398"/>
          </default>
          <default class="left_knuckle">
              <joint axis="0 -1 0" range="-0.349066 0.349066"/>
              <position ctrlrange="-0.349066 0.349066"/>
          </default>
          <default class="left_proximal">
              <joint range="-0.261799 1.5708"/>
              <position ctrlrange="-0.261799 1.5708"/>
          </default>
          <default class="left_middle_distal">
              <joint range="0 1.5708"/>
              <position kp="0.5" ctrlrange="0 3.1415"/>
          </default>

          <default class="left_plastic">
              <geom solimp="0.5 0.99 0.0001" solref="0.005 1"/>
              <default class="left_plastic_visual">
                  <geom type="mesh" material="black" contype="0" conaffinity="0" group="2"/>
              </default>
              <default class="left_plastic_collision">
                  <geom group="3"/>
              </default>
          </default>
      </default>
  </default>

  <asset>
    <material name="black" specular="0.5" shininess="0.25" rgba="0.16355 0.16355 0.16355 1"/>
    <material name="gray" specular="0.0" shininess="0.25" rgba="0.80848 0.80848 0.80848 1"/>
    <material name="metallic" specular="0" shininess="0.25" rgba="0.9 0.9 0.9 1"/>

    <mesh class="left_hand" file="assets/forearm_0.obj" name="left_forearm_0"/>
    <mesh class="left_hand" file="assets/forearm_1.obj" name="left_forearm_1"/>
    <mesh class="left_hand" file="assets/forearm_collision.obj" name="left_forearm_collision"/>
    <mesh class="left_hand" file="assets/wrist.obj" scale="-0.001 0.001 0.001" name="left_wrist"/>
    <mesh class="left_hand" file="assets/palm.obj" scale="-0.001 0.001 0.001" name="left_palm"/>
    <mesh class="left_hand" file="assets/f_knuckle.obj" name="left_f_knuckle"/>
    <mesh class="left_hand" file="assets/f_proximal.obj" name="left_f_proximal"/>
    <mesh class="left_hand" file="assets/f_middle.obj" name="left_f_middle"/>
    <mesh class="left_hand" file="assets/f_distal_pst.obj" name="left_f_distal_pst"/>
    <mesh class="left_hand" file="assets/lf_metacarpal.obj" scale="-0.001 0.001 0.001" name="left_lf_metacarpal"/>
    <mesh class="left_hand" file="assets/th_proximal.obj" name="left_th_proximal"/>
    <mesh class="left_hand" file="assets/th_middle.obj" name="left_th_middle"/>
    <mesh class="left_hand" file="assets/th_distal_pst.obj" name="left_th_distal_pst"/>

    <include file="left_forearm_collision_collision_assets.xml"/>
    <include file="left_palm_collision_assets.xml"/>
    <include file="left_f_proximal_collision_assets.xml"/>
    <include file="left_f_middle_collision_assets.xml"/>
    <include file="left_f_distal_pst_collision_assets.xml"/>
    <include file="left_lf_metacarpal_collision_assets.xml"/>
    <include file="left_th_proximal_collision_assets.xml"/>
    <include file="left_th_middle_collision_assets.xml"/>
    <include file="left_th_distal_pst_collision_assets.xml"/>
  </asset>


  <worldbody>
    <body name="lh_forearm" childclass="left_hand" quat="1 1 1 1" pos="-0.3 0 0.2" gravcomp="1">
      <joint name="base_mount_joint_x" type="slide" axis="-1 0 0" damping="50" range="-1 1"/>
      <joint name="base_mount_joint_y" type="slide" axis="0 0 1" damping="50" range="-1 1"/>
      <joint name="base_mount_joint_z" type="slide" axis="0 1 0" damping="50" range="-1 1"/>
      <joint name="base_mount_joint_roll" type="hinge" axis="1 0 0" damping="0.5" range="-3.14159 3.14159"/>
      <joint name="base_mount_joint_pitch" type="hinge" axis="0 0 1" damping="0.5" range="-3.14159 3.14159"/>
      <joint name="base_mount_joint_yaw" type="hinge" axis="0 1 0" damping="0.5" range="-3.14159 3.14159"/>
      <!-- <site name="lh_forearm_touch" class="left_hand" pos="0 0 0.08" zaxis="0 1 0"/> -->
      <inertial mass="3" pos="0 0 0.09" diaginertia="0.0138 0.0138 0.00744"/>
      <!-- <geom class="left_plastic_visual" mesh="left_forearm_0" material="gray"/> -->
      <!-- <geom class="left_plastic_visual" mesh="left_forearm_1"/> -->
      <!-- <include file="tactile_envs/assets/shadow_hand_submodel/left_forearm_collision_collision_0.xml"/> -->
      <!-- <geom class="left_plastic_collision" size="0.03 0.03 0.03" pos="0 -0.01 0.181" quat="0.924909 0 0.380188 0" -->
        <!-- type="box"/> -->
      <body name="lh_wrist" pos="0 -0.01 0.21301" gravcomp="1">
      <!-- <body name="lh_wrist" pos="0 -0.01 0.15301" quat="1 0 0 1"> -->
        <inertial mass="0.1" pos="0 0 0.029" quat="0.5 0.5 0.5 0.5" diaginertia="6.4e-05 4.38e-05 3.5e-05"/>
        <joint class="left_wrist_y" name="lh_WRJ2"/>
        <geom class="left_plastic_visual" mesh="left_wrist" material="metallic"/>
        <!-- <geom size="0.013 0.015" quat="0.499998 0.5 0.5 -0.500002" type="cylinder" class="left_plastic_collision"/> -->
        <geom size="0.011 0.005" pos="0.026 0 0.034" quat="1 0 1 0" type="cylinder" class="left_plastic_collision"/>
        <geom size="0.011 0.005" pos="-0.031 0 0.034" quat="1 0 1 0" type="cylinder" class="left_plastic_collision"/>
        <geom size="0.0135 0.009 0.005" pos="0.021 0 0.011" quat="-0.923879 0 0.382684 0" type="box"
          class="left_plastic_collision"/>
        <geom size="0.0135 0.009 0.005" pos="-0.026 0 0.01" quat="-0.923879 0 -0.382684 0" type="box"
          class="left_plastic_collision"/>
        <body name="lh_palm" pos="0 0 0.034" gravcomp="1">
          <site name="lh_palm_touch" class="left_hand" pos="0 0 0.05" zaxis="0 1 0"/>
          <inertial mass="0.3" pos="0 0 0.035" quat="1 0 0 1" diaginertia="0.0005287 0.0003581 0.000191"/>
          <joint class="left_wrist_x" name="lh_WRJ1"/>
          <geom class="left_plastic_visual" mesh="left_palm"/>
          <include file="left_palm_collision_0.xml"/>
          <body name="lh_ffknuckle" pos="-0.033 0 0.095" gravcomp="1">
            <inertial mass="0.008" pos="0 0 0" quat="0.5 0.5 -0.5 0.5" diaginertia="3.2e-07 2.6e-07 2.6e-07"/>
            <joint name="lh_FFJ4" class="left_knuckle" axis="0 1 0"/>
            <geom pos="0 0 0.0005" class="left_plastic_visual" mesh="left_f_knuckle" material="metallic"/>
            <geom size="0.009 0.009" quat="1 0 1 0" type="cylinder" class="left_plastic_collision"/>
            <body name="lh_ffproximal" gravcomp="1">
              <site name="lh_ffproximal_touch" class="left_hand" pos="0 0 0.022" zaxis="0 1 0"/>
              <inertial mass="0.03" pos="0 0 0.0225" quat="1 0 0 1" diaginertia="1e-05 9.8e-06 1.8e-06"/>
              <joint name="lh_FFJ3" class="left_proximal"/>
              <geom class="left_plastic_visual" mesh="left_f_proximal"/>
              <include file="left_f_proximal_collision_0.xml"/>
              <body name="lh_ffmiddle" pos="0 0 0.045" gravcomp="1">
                <site name="lh_ffmiddle_touch" class="left_hand" pos="0 0 0.0125" zaxis="0 1 0"/>
                <inertial mass="0.017" pos="0 0 0.0125" quat="1 0 0 1" diaginertia="2.7e-06 2.6e-06 8.7e-07"/>
                <joint name="lh_FFJ2" class="left_middle_distal"/>
                <geom class="left_plastic_visual" mesh="left_f_middle"/>
                <include file="left_f_middle_collision_0.xml"/>
                <body name="lh_ffdistal" pos="0 0 0.025" gravcomp="1">
                  <site name="lh_ffdistal_touch" class="left_hand" pos="0 0 0.017" zaxis="0 1 0"/>
                  <inertial mass="0.013" pos="0 0 0.0130769" quat="1 0 0 1"
                    diaginertia="1.28092e-06 1.12092e-06 5.3e-07"/>
                  <joint name="lh_FFJ1" class="left_middle_distal"/>
                  <geom class="left_plastic_visual" mesh="left_f_distal_pst"/>
                  <include file="left_f_distal_pst_collision_0.xml"/>
                </body>
              </body>
            </body>
          </body>
          <body name="lh_mfknuckle" pos="-0.011 0 0.099" gravcomp="1">
            <inertial mass="0.008" pos="0 0 0" quat="0.5 0.5 -0.5 0.5" diaginertia="3.2e-07 2.6e-07 2.6e-07"/>
            <joint name="lh_MFJ4" class="left_knuckle" axis="0 1 0"/>
            <geom pos="0 0 0.0005" class="left_plastic_visual" mesh="left_f_knuckle" material="metallic"/>
            <geom size="0.009 0.009" quat="1 0 1 0" type="cylinder" class="left_plastic_collision"/>
            <body name="lh_mfproximal" gravcomp="1">
              <site name="lh_mfproximal_touch" class="left_hand" pos="0 0 0.022" zaxis="0 1 0"/>
              <inertial mass="0.03" pos="0 0 0.0225" quat="1 0 0 1" diaginertia="1e-05 9.8e-06 1.8e-06"/>
              <joint name="lh_MFJ3" class="left_proximal"/>
              <geom class="left_plastic_visual" mesh="left_f_proximal"/>
              <include file="left_f_proximal_collision_1.xml"/>
              <body name="lh_mfmiddle" pos="0 0 0.045" gravcomp="1">
                <site name="lh_mfmiddle_touch" class="left_hand" pos="0 0 0.0125" zaxis="0 1 0"/>
                <inertial mass="0.017" pos="0 0 0.0125" quat="1 0 0 1" diaginertia="2.7e-06 2.6e-06 8.7e-07"/>
                <joint name="lh_MFJ2" class="left_middle_distal"/>
                <geom class="left_plastic_visual" mesh="left_f_middle"/>
                <include file="left_f_middle_collision_1.xml"/>
                <body name="lh_mfdistal" pos="0 0 0.025" gravcomp="1">
                  <site name="lh_mfdistal_touch" class="left_hand" pos="0 0 0.017" zaxis="0 1 0"/>
                  <inertial mass="0.013" pos="0 0 0.0130769" quat="1 0 0 1"
                    diaginertia="1.28092e-06 1.12092e-06 5.3e-07"/>
                  <joint name="lh_MFJ1" class="left_middle_distal"/>
                  <geom class="left_plastic_visual" mesh="left_f_distal_pst"/>
                  <include file="left_f_distal_pst_collision_1.xml"/>
                </body>
              </body>
            </body>
          </body>
          <body name="lh_rfknuckle" pos="0.011 0 0.095" gravcomp="1">
            <inertial mass="0.008" pos="0 0 0" quat="0.5 0.5 -0.5 0.5" diaginertia="3.2e-07 2.6e-07 2.6e-07"/>
            <joint name="lh_RFJ4" class="left_knuckle"/>
            <geom pos="0 0 0.0005" class="left_plastic_visual" mesh="left_f_knuckle" material="metallic"/>
            <geom size="0.009 0.009" quat="1 0 1 0" type="cylinder" class="left_plastic_collision"/>
            <body name="lh_rfproximal" gravcomp="1">
              <site name="lh_rfproximal_touch" class="left_hand" pos="0 0 0.022" zaxis="0 1 0"/>
              <inertial mass="0.03" pos="0 0 0.0225" quat="1 0 0 1" diaginertia="1e-05 9.8e-06 1.8e-06"/>
              <joint name="lh_RFJ3" class="left_proximal"/>
              <geom class="left_plastic_visual" mesh="left_f_proximal"/>
              <include file="left_f_proximal_collision_2.xml"/>
              <body name="lh_rfmiddle" pos="0 0 0.045" gravcomp="1">
                <site name="lh_rfmiddle_touch" class="left_hand" pos="0 0 0.0125" zaxis="0 1 0"/>
                <inertial mass="0.017" pos="0 0 0.0125" quat="1 0 0 1" diaginertia="2.7e-06 2.6e-06 8.7e-07"/>
                <joint name="lh_RFJ2" class="left_middle_distal"/>
                <geom class="left_plastic_visual" mesh="left_f_middle"/>
                <include file="left_f_middle_collision_2.xml"/>
                <body name="lh_rfdistal" pos="0 0 0.025" gravcomp="1">
                  <site name="lh_rfdistal_touch" class="left_hand" pos="0 0 0.017" zaxis="0 1 0"/>
                  <inertial mass="0.013" pos="0 0 0.0130769" quat="1 0 0 1"
                    diaginertia="1.28092e-06 1.12092e-06 5.3e-07"/>
                  <joint name="lh_RFJ1" class="left_middle_distal"/>
                  <geom class="left_plastic_visual" mesh="left_f_distal_pst"/>
                  <include file="left_f_distal_pst_collision_2.xml"/>
                </body>
              </body>
            </body>
          </body>
          <body name="lh_lfmetacarpal" pos="0.033 0 0.02071" gravcomp="1">
            <site name="lh_lfmetacarpal_touch" class="left_hand" pos="0 0 0.035" zaxis="0 1 0"/>
            <inertial mass="0.03" pos="0 0 0.04" quat="1 0 0 1" diaginertia="1.638e-05 1.45e-05 4.272e-06"/>
            <joint name="lh_LFJ5" class="left_metacarpal" axis="0.573576 0 -0.819152"/>
            <geom class="left_plastic_visual" mesh="left_lf_metacarpal"/>
            <include file='left_lf_metacarpal_collision_0.xml'/>
            <body name="lh_lfknuckle" pos="0 0 0.06579" gravcomp="1">
              <inertial mass="0.008" pos="0 0 0" quat="0.5 0.5 -0.5 0.5" diaginertia="3.2e-07 2.6e-07 2.6e-07"/>
              <joint name="lh_LFJ4" class="left_knuckle"/>
              <geom pos="0 0 0.0005" class="left_plastic_visual" mesh="left_f_knuckle" material="metallic"/>
              <geom size="0.009 0.009" quat="1 0 1 0" type="cylinder" class="left_plastic_collision"/>
              <body name="lh_lfproximal" gravcomp="1">
                <site name="lh_lfproximal_touch" class="left_hand" pos="0 0 0.022" zaxis="0 1 0"/>
                <inertial mass="0.03" pos="0 0 0.0225" quat="1 0 0 1" diaginertia="1e-05 9.8e-06 1.8e-06"/>
                <joint name="lh_LFJ3" class="left_proximal"/>
                <geom class="left_plastic_visual" mesh="left_f_proximal"/>
                <include file="left_f_proximal_collision_3.xml"/>
                <body name="lh_lfmiddle" pos="0 0 0.045" gravcomp="1">
                  <site name="lh_lfmiddle_touch" class="left_hand" pos="0 0 0.0125" zaxis="0 1 0"/>
                  <inertial mass="0.017" pos="0 0 0.0125" quat="1 0 0 1" diaginertia="2.7e-06 2.6e-06 8.7e-07"/>
                  <joint name="lh_LFJ2" class="left_middle_distal"/>
                  <geom class="left_plastic_visual" mesh="left_f_middle"/>
                  <include file="left_f_middle_collision_3.xml"/>
                  <body name="lh_lfdistal" pos="0 0 0.025">
                    <site name="lh_lfdistal_touch" class="left_hand" pos="0 0 0.017" zaxis="0 1 0"/>
                    <inertial mass="0.013" pos="0 0 0.0130769" quat="1 0 0 1"
                      diaginertia="1.28092e-06 1.12092e-06 5.3e-07"/>
                    <joint name="lh_LFJ1" class="left_middle_distal"/>
                    <geom class="left_plastic_visual" mesh="left_f_distal_pst"/>
                    <include file="left_f_distal_pst_collision_3.xml"/>
                  </body>
                </body>
              </body>
            </body>
          </body>
          <body name="lh_thbase" pos="-0.034 -0.00858 0.029" quat="0 -0.382683 0 0.92388" gravcomp="1">
            <inertial mass="0.01" pos="0 0 0" diaginertia="1.6e-07 1.6e-07 1.6e-07"/>
            <joint name="lh_THJ5" class="left_thbase"/>
            <body name="lh_thproximal" gravcomp="1">
              <site name="lh_thproximal_touch" class="left_hand" pos="0 0 0.02" zaxis="1 0 0"/>
              <inertial mass="0.04" pos="0 0 0.019" diaginertia="1.36e-05 1.36e-05 3.13e-06"/>
              <joint name="lh_THJ4" class="left_thproximal"/>
              <geom class="left_plastic_visual" mesh="left_th_proximal"/>
              <include file='left_th_proximal_collision_0.xml'/>
              <body name="lh_thhub" pos="0 0 0.038" gravcomp="1">
                <inertial mass="0.005" pos="0 0 0" diaginertia="1e-06 1e-06 3e-07"/>
                <joint name="lh_THJ3" class="left_thhub"/>
                <body name="lh_thmiddle" gravcomp="1">
                  <site name="lh_thmiddle_touch" class="left_hand" pos="0 0 0.014" zaxis="1 0 0"/>
                  <inertial mass="0.02" pos="0 0 0.016" diaginertia="5.1e-06 5.1e-06 1.21e-06"/>
                  <joint name="lh_THJ2" class="left_thmiddle"/>
                  <geom class="left_plastic_visual" mesh="left_th_middle"/>
                  <include file='left_th_middle_collision_0.xml'/>
                  <body name="lh_thdistal" pos="0 0 0.032" quat="1 0 0 -1" gravcomp="1">
                    <site name="lh_thdistal_touch" class="left_hand" pos="0 0 0.02" zaxis="0 1 0"/>
                    <inertial mass="0.017" pos="0 0 0.0145588" quat="1 0 0 1"
                      diaginertia="2.37794e-06 2.27794e-06 1e-06"/>
                    <joint name="lh_THJ1" class="left_thdistal"/>
                    <geom class="left_plastic_visual" mesh="left_th_distal_pst"/>
                    <include file='left_th_distal_pst_collision_0.xml'/>
                  </body>
                </body>
              </body>
            </body>
          </body>
        </body>
      </body>
    </body>

  </worldbody>
  
  <contact>
      <!-- <exclude body1="lh_wrist" body2="lh_forearm"/> -->
      <exclude body1="lh_thproximal" body2="lh_thmiddle"/>
      <exclude body1="lh_palm" body2="lh_thproximal"/>
      <exclude body1="lh_palm" body2="lh_lfproximal"/>
      <exclude body1="lh_palm" body2="lh_rfproximal"/>
      <exclude body1="lh_palm" body2="lh_mfproximal"/>
      <exclude body1="lh_palm" body2="lh_ffproximal"/>
      <exclude body1="lh_lfmetacarpal" body2="lh_lfproximal"/>
  </contact>

  <tendon>
      <fixed name="lh_FFJ0">
          <joint joint="lh_FFJ2" coef="1"/>
          <joint joint="lh_FFJ1" coef="1"/>
      </fixed>
      <fixed name="lh_MFJ0">
          <joint joint="lh_MFJ2" coef="1"/>
          <joint joint="lh_MFJ1" coef="1"/>
      </fixed>
      <fixed name="lh_RFJ0">
          <joint joint="lh_RFJ2" coef="1"/>
          <joint joint="lh_RFJ1" coef="1"/>
      </fixed>
      <fixed name="lh_LFJ0">
          <joint joint="lh_LFJ2" coef="1"/>
          <joint joint="lh_LFJ1" coef="1"/>
      </fixed>
  </tendon>

  <actuator>
      <position name="lh_A_WRJ2" joint="lh_WRJ2" class="left_wrist_y"/>
      <position name="lh_A_WRJ1" joint="lh_WRJ1" class="left_wrist_x"/>
      <position name="lh_A_THJ5" joint="lh_THJ5" class="left_thbase"/>
      <position name="lh_A_THJ4" joint="lh_THJ4" class="left_thproximal"/>
      <position name="lh_A_THJ3" joint="lh_THJ3" class="left_thhub"/>
      <position name="lh_A_THJ2" joint="lh_THJ2" class="left_thmiddle"/>
      <position name="lh_A_THJ1" joint="lh_THJ1" class="left_thdistal"/>
      <position name="lh_A_FFJ4" joint="lh_FFJ4" class="left_knuckle"/>
      <position name="lh_A_FFJ3" joint="lh_FFJ3" class="left_proximal"/>
      <position name="lh_A_FFJ0" tendon="lh_FFJ0" class="left_middle_distal"/>
      <position name="lh_A_MFJ4" joint="lh_MFJ4" class="left_knuckle"/>
      <position name="lh_A_MFJ3" joint="lh_MFJ3" class="left_proximal"/>
      <position name="lh_A_MFJ0" tendon="lh_MFJ0" class="left_middle_distal"/>
      <position name="lh_A_RFJ4" joint="lh_RFJ4" class="left_knuckle"/>
      <position name="lh_A_RFJ3" joint="lh_RFJ3" class="left_proximal"/>
      <position name="lh_A_RFJ0" tendon="lh_RFJ0" class="left_middle_distal"/>
      <position name="lh_A_LFJ5" joint="lh_LFJ5" class="left_metacarpal"/>
      <position name="lh_A_LFJ4" joint="lh_LFJ4" class="left_knuckle"/>
      <position name="lh_A_LFJ3" joint="lh_LFJ3" class="left_proximal"/>
      <position name="lh_A_LFJ0" tendon="lh_LFJ0" class="left_middle_distal"/>
  </actuator>

</mujoco>
